#faster than insert into
#but harder to identify when and where error occured

import pymysql

try:
    conn_local = self.ctx.get_mysql_connection("local")
    cur = conn_local.cursor(pymysql.cursors.DictCursor)
    q1 = '''
      LOAD DATA LOCAL INFILE '/home/tide/project/py/github.com/tidesquare/trendy/out/privia/booking_data.csv'
      INTO TABLE sakila.booking_data
      fields terminated by ',' LINES TERMINATED BY '\n';
      '''

    cur.execute(q1)
    conn_local.commit()
except Exception as e:
    print(traceback.format_exc())
    print(sys.exc_info()[2])
finally:
    print('booking_data.csv has been uploaded!')
    cur.close()
    conn_local.close()
    
